[SSL] 憑證不存在，Goblin 正在召喚魔法陣...
[SSL] 憑證召喚成功！
 * Debugger is active!
 * Debugger PIN: 731-043-386
[SSL] 啟動失敗，改用非加密模式：[Errno 9] Bad file descriptor
 * Debugger is active!
 * Debugger PIN: 731-043-386
Traceback (most recent call last):
  File "/home/steve/desk/HNAS/./app.py", line 525, in run_server
    app.run(ssl_context=(CRT, KEY), debug=True, host='0.0.0.0', port=5000)
  File "/home/steve/desk/HNAS/hnas_env/lib/python3.12/site-packages/flask/app.py", line 662, in run
    run_simple(t.cast(str, host), port, self, **options)
  File "/home/steve/desk/HNAS/hnas_env/lib/python3.12/site-packages/werkzeug/serving.py", line 1093, in run_simple
    srv = make_server(
          ^^^^^^^^^^^^
  File "/home/steve/desk/HNAS/hnas_env/lib/python3.12/site-packages/werkzeug/serving.py", line 930, in make_server
    return ThreadedWSGIServer(
           ^^^^^^^^^^^^^^^^^^^
  File "/home/steve/desk/HNAS/hnas_env/lib/python3.12/site-packages/werkzeug/serving.py", line 792, in __init__
    self.socket = socket.fromfd(fd, address_family, socket.SOCK_STREAM)
                  ^^^^^^^^^^^^^^^^^^^^^^^^^^^^^^^^^^^^^^^^^^^^^^^^^^^^^
  File "/usr/lib/python3.12/socket.py", line 547, in fromfd
    nfd = dup(fd)
          ^^^^^^^
OSError: [Errno 9] Bad file descriptor

During handling of the above exception, another exception occurred:

Traceback (most recent call last):
  File "/home/steve/desk/HNAS/./app.py", line 531, in <module>
    run_server()
  File "/home/steve/desk/HNAS/./app.py", line 528, in run_server
    app.run(debug=True, host='0.0.0.0', port=5000)
  File "/home/steve/desk/HNAS/hnas_env/lib/python3.12/site-packages/flask/app.py", line 662, in run
    run_simple(t.cast(str, host), port, self, **options)
  File "/home/steve/desk/HNAS/hnas_env/lib/python3.12/site-packages/werkzeug/serving.py", line 1093, in run_simple
    srv = make_server(
          ^^^^^^^^^^^^
  File "/home/steve/desk/HNAS/hnas_env/lib/python3.12/site-packages/werkzeug/serving.py", line 930, in make_server
    return ThreadedWSGIServer(
           ^^^^^^^^^^^^^^^^^^^
  File "/home/steve/desk/HNAS/hnas_env/lib/python3.12/site-packages/werkzeug/serving.py", line 792, in __init__
    self.socket = socket.fromfd(fd, address_family, socket.SOCK_STREAM)
                  ^^^^^^^^^^^^^^^^^^^^^^^^^^^^^^^^^^^^^^^^^^^^^^^^^^^^^
  File "/usr/lib/python3.12/socket.py", line 547, in fromfd
    nfd = dup(fd)
          ^^^^^^^
OSError: [Errno 9] Bad file descriptor
 * Serving Flask app 'app'
 * Debug mode: on
Address already in use
Port 5000 is in use by another program. Either identify and stop that program, or start the server with a different port.
(hnas_env) steve@steve-Latitude-E7270:~/desk/HNAS$ 

